Traceback (most recent call last):
  File "<string>", line 1, in <module>
  File "C:\Users\QbaSo\AppData\Local\Programs\Python\Python39\lib\multiprocessing\spawn.py", line 116, in spawn_main
    exitcode = _main(fd, parent_sentinel)
  File "C:\Users\QbaSo\AppData\Local\Programs\Python\Python39\lib\multiprocessing\spawn.py", line 125, in _main
    prepare(preparation_data)
  File "C:\Users\QbaSo\AppData\Local\Programs\Python\Python39\lib\multiprocessing\spawn.py", line 236, in prepare
    _fixup_main_from_path(data['init_main_from_path'])
  File "C:\Users\QbaSo\AppData\Local\Programs\Python\Python39\lib\multiprocessing\spawn.py", line 287, in _fixup_main_from_path
    main_content = runpy.run_path(main_path,
  File "C:\Users\QbaSo\AppData\Local\Programs\Python\Python39\lib\runpy.py", line 268, in run_path
    return _run_module_code(code, init_globals, run_name,
  File "C:\Users\QbaSo\AppData\Local\Programs\Python\Python39\lib\runpy.py", line 97, in _run_module_code
    _run_code(code, mod_globals, init_globals,
  File "C:\Users\QbaSo\AppData\Local\Programs\Python\Python39\lib\runpy.py", line 87, in _run_code
    exec(code, run_globals)
  File "c:\Users\QbaSo\Desktop\praca magisterska\myCode\samllNetCL TaskIL Noise Rehersal.py", line 50, in <module>
    train_losses, tasks_losses, exemplers = train_validation_all_classes(model, optimizer, tasks, rehersal_loader, epoch=1, log_interval = 10)
  File "c:\Users\QbaSo\Desktop\praca magisterska\myCode\taskIL.py", line 11, in train_validation_all_classes
    rehersal_iterator = iter(rehersal_loader)
  File "C:\Users\QbaSo\AppData\Local\Programs\Python\Python39\lib\site-packages\torch\utils\data\dataloader.py", line 435, in __iter__
    return self._get_iterator()
  File "C:\Users\QbaSo\AppData\Local\Programs\Python\Python39\lib\site-packages\torch\utils\data\dataloader.py", line 381, in _get_iterator
    return _MultiProcessingDataLoaderIter(self)
  File "C:\Users\QbaSo\AppData\Local\Programs\Python\Python39\lib\site-packages\torch\utils\data\dataloader.py", line 1034, in __init__
    w.start()
  File "C:\Users\QbaSo\AppData\Local\Programs\Python\Python39\lib\multiprocessing\process.py", line 121, in start
    self._popen = self._Popen(self)
  File "C:\Users\QbaSo\AppData\Local\Programs\Python\Python39\lib\multiprocessing\context.py", line 224, in _Popen
    return _default_context.get_context().Process._Popen(process_obj)
  File "C:\Users\QbaSo\AppData\Local\Programs\Python\Python39\lib\multiprocessing\context.py", line 327, in _Popen
    return Popen(process_obj)
  File "C:\Users\QbaSo\AppData\Local\Programs\Python\Python39\lib\multiprocessing\popen_spawn_win32.py", line 45, in __init__
    prep_data = spawn.get_preparation_data(process_obj._name)
  File "C:\Users\QbaSo\AppData\Local\Programs\Python\Python39\lib\multiprocessing\spawn.py", line 154, in get_preparation_data
    _check_not_importing_main()
  File "C:\Users\QbaSo\AppData\Local\Programs\Python\Python39\lib\multiprocessing\spawn.py", line 134, in _check_not_importing_main
    raise RuntimeError('''
RuntimeError:
        An attempt has been made to start a new process before the
        current process has finished its bootstrapping phase.
        This probably means that you are not using fork to start your
        child processes and you have forgotten to use the proper idiom
        in the main module:
            if __name__ == '__main__':
                freeze_support()
                ...
        The "freeze_support()" line can be omitted if the program
